Traceback (most recent call last):
  File "/Users/avaj0001/Documents/projects/deep_gw_pe_followup/venv/lib/python3.9/site-packages/jupyter_cache/executors/utils.py", line 58, in single_nb_execution
    executenb(
  File "/Users/avaj0001/Documents/projects/deep_gw_pe_followup/venv/lib/python3.9/site-packages/nbclient/client.py", line 1204, in execute
    return NotebookClient(nb=nb, resources=resources, km=km, **kwargs).execute()
  File "/Users/avaj0001/Documents/projects/deep_gw_pe_followup/venv/lib/python3.9/site-packages/nbclient/util.py", line 84, in wrapped
    return just_run(coro(*args, **kwargs))
  File "/Users/avaj0001/Documents/projects/deep_gw_pe_followup/venv/lib/python3.9/site-packages/nbclient/util.py", line 62, in just_run
    return loop.run_until_complete(coro)
  File "/usr/local/Cellar/python@3.9/3.9.16/Frameworks/Python.framework/Versions/3.9/lib/python3.9/asyncio/base_events.py", line 647, in run_until_complete
    return future.result()
  File "/Users/avaj0001/Documents/projects/deep_gw_pe_followup/venv/lib/python3.9/site-packages/nbclient/client.py", line 663, in async_execute
    await self.async_execute_cell(
  File "/Users/avaj0001/Documents/projects/deep_gw_pe_followup/venv/lib/python3.9/site-packages/nbclient/client.py", line 965, in async_execute_cell
    await self._check_raise_for_error(cell, cell_index, exec_reply)
  File "/Users/avaj0001/Documents/projects/deep_gw_pe_followup/venv/lib/python3.9/site-packages/nbclient/client.py", line 862, in _check_raise_for_error
    raise CellExecutionError.from_cell_and_msg(cell, exec_reply_content)
nbclient.exceptions.CellExecutionError: An error occurred while executing the following cell:
------------------
h_reconstructed = from_wavelet_to_time(h_wavelet, Nf=Nf, Nt=Nt, mult=mult)
fig = plot_time_domain_signal(ts, h_reconstructed, freq_range)
------------------

[0;31m---------------------------------------------------------------------------[0m
[0;31mNameError[0m                                 Traceback (most recent call last)
[0;32m/var/folders/qt/rxjvm_j566v9qn7g754s1v9hzb3p7f/T/ipykernel_52338/3710908209.py[0m in [0;36m<cell line: 1>[0;34m()[0m
[0;32m----> 1[0;31m [0mh_reconstructed[0m [0;34m=[0m [0mfrom_wavelet_to_time[0m[0;34m([0m[0mh_wavelet[0m[0;34m,[0m [0mNf[0m[0;34m=[0m[0mNf[0m[0;34m,[0m [0mNt[0m[0;34m=[0m[0mNt[0m[0;34m,[0m [0mmult[0m[0;34m=[0m[0mmult[0m[0;34m)[0m[0;34m[0m[0;34m[0m[0m
[0m[1;32m      2[0m [0mfig[0m [0;34m=[0m [0mplot_time_domain_signal[0m[0;34m([0m[0mts[0m[0;34m,[0m [0mh_reconstructed[0m[0;34m,[0m [0mfreq_range[0m[0;34m)[0m[0;34m[0m[0;34m[0m[0m

[0;31mNameError[0m: name 'from_wavelet_to_time' is not defined
NameError: name 'from_wavelet_to_time' is not defined

